<?xml version="1.0"?>
<robot name="myfirst">
  <link name="base_link">
    <visual>
    <origin xyz="0 0 0" rpy="0 0 0"/>
      <geometry>
        <cylinder length="0.6" radius="0.2"/>
      </geometry>
    </visual>
  </link>
  
  <link name="child_link">
    <visual>
      <geometry>
        <box size="0.5 0.2 0.1"/>
      </geometry>
      <origin xyz="0 0 0" rpy="0 0 0"/>
    </visual>
  </link>
  
  <joint name="base_child_joint" type="fixed">
  <parent link="base_link"/>
  <child link="child_link"/>
  <origin xyz="0 0 0.3" rpy="0 0 0"/>
  </joint>

  <link name="right_wheel">
    <visual>
      <geometry>
        <cylinder length="0.1" radius="0.1"/>
      </geometry>
      <origin xyz="0 0 0" rpy="1.57 0 0"/>
    </visual>
  </link>
  
  <joint name="base_right_wheel_joint" type="continuous">
  <parent link="base_link"/>
  <child link="right_wheel"/>
  <origin xyz="0 0.25 0"/>
  <axis xyz="0 1 0"/>
  </joint>
</robot>
